I'm sorry, but an uncaught exception occurred.

While running game code:
  File "game/script.rpy", line 243, in script
    s_1 "-Надо поспешить, времени мало"
Exception: Sayer 's_1' is not defined.

-- Full Traceback ------------------------------------------------------------

Full traceback:
  File "game/script.rpy", line 243, in script
    s_1 "-Надо поспешить, времени мало"
  File "C:\Users\mrdan\OneDrive\Рабочий стол\renpy\renpy-8.2.1-sdk\renpy\ast.py", line 2557, in execute
    Say.execute(self)
  File "C:\Users\mrdan\OneDrive\Рабочий стол\renpy\renpy-8.2.1-sdk\renpy\ast.py", line 575, in execute
    who = eval_who(self.who, self.who_fast)
  File "C:\Users\mrdan\OneDrive\Рабочий стол\renpy\renpy-8.2.1-sdk\renpy\ast.py", line 464, in eval_who
    raise Exception("Sayer '%s' is not defined." % who)
Exception: Sayer 's_1' is not defined.

Windows-10-10.0.22631 AMD64
Ren'Py 8.2.1.24030407
rsuegame 1.0
Fri May 24 09:14:17 2024
